<?xml version="1.0" ?>
<robot name="robot_arm" xmlns:xacro="http://www.ros.org/wiki/xacro">

  <link name="base_link">
    <inertial>
      <origin xyz="0.0046536909454116026 1.0519874642441434e-06 0.06573158511890381" rpy="0 0 0"/>
      <mass value="22.818233507060175"/>
      <inertia ixx="0.094009" iyy="0.109119" izz="0.092973" ixy="-3e-06" iyz="-3e-06" ixz="-0.013727"/>
    </inertial>
    <visual>
      <origin xyz="0 0 0" rpy="0 0 0"/>
      <geometry>
        <mesh filename="file://$(find robot_arm_description)/meshes/base_link.stl" scale="0.001 0.001 0.001"/>
      </geometry>
      <material name="silver">
        <color rgba="0.700 0.700 0.700 1.000"/>
      </material>
    </visual>
    <collision>
      <origin xyz="0 0 0" rpy="0 0 0"/>
      <geometry>
        <mesh filename="file://$(find robot_arm_description)/meshes/base_link.stl" scale="0.001 0.001 0.001"/>
      </geometry>
    </collision>
  </link>

  <link name="shoulder_1">
    <inertial>
      <origin xyz="-0.0491886141288093 3.0049648042576673e-05 0.18122774512466278" rpy="0 0 0"/>
      <mass value="6.109721005425743"/>
      <inertia ixx="0.066229" iyy="0.080655" izz="0.01662" ixy="0.0" iyz="-7e-06" ixz="0.010958"/>
    </inertial>
    <visual>
      <origin xyz="-0.03435 -0.0 -0.194998" rpy="0 0 0"/>
      <geometry>
        <mesh filename="file://$(find robot_arm_description)/meshes/shoulder_1.stl" scale="0.001 0.001 0.001"/>
      </geometry>
      <material name="silver">
        <color rgba="0.700 0.700 0.700 1.000"/>
      </material>
    </visual>
    <collision>
      <origin xyz="-0.03435 -0.0 -0.194998" rpy="0 0 0"/>
      <geometry>
        <mesh filename="file://$(find robot_arm_description)/meshes/shoulder_1.stl" scale="0.001 0.001 0.001"/>
      </geometry>
    </collision>
  </link>

  <link name="elbow_1">
    <inertial>
      <origin xyz="0.019461342587672934 0.03531796910493689 -0.013364126604368143" rpy="0 0 0"/>
      <mass value="1.7303290262635433"/>
      <inertia ixx="0.003527" iyy="0.002531" izz="0.00161" ixy="2e-05" iyz="-0.00013" ixz="-4e-06"/>
    </inertial>
    <visual>
      <origin xyz="0.02165 -0.0 -0.499847" rpy="0 0 0"/>
      <geometry>
        <mesh filename="file://$(find robot_arm_description)/meshes/elbow_1.stl" scale="0.001 0.001 0.001"/>
      </geometry>
      <material name="silver">
        <color rgba="0.700 0.700 0.700 1.000"/>
      </material>
    </visual>
    <collision>
      <origin xyz="0.02165 -0.0 -0.499847" rpy="0 0 0"/>
      <geometry>
        <mesh filename="file://$(find robot_arm_description)/meshes/elbow_1.stl" scale="0.001 0.001 0.001"/>
      </geometry>
    </collision>
  </link>

  <link name="wrist_1">
    <inertial>
      <origin xyz="-0.026164068859008547 7.841148618109584e-05 0.17543826901390325" rpy="0 0 0"/>
      <mass value="3.6709371223534295"/>
      <inertia ixx="0.021907" iyy="0.030357" izz="0.009426" ixy="-5e-06" iyz="-1.6e-05" ixz="0.006484"/>
    </inertial>
    <visual>
      <origin xyz="0.002143 -0.004932 -0.556934" rpy="0 0 0"/>
      <geometry>
        <mesh filename="file://$(find robot_arm_description)/meshes/wrist_1.stl" scale="0.001 0.001 0.001"/>
      </geometry>
      <material name="silver">
        <color rgba="0.700 0.700 0.700 1.000"/>
      </material>
    </visual>
    <collision>
      <origin xyz="0.002143 -0.004932 -0.556934" rpy="0 0 0"/>
      <geometry>
        <mesh filename="file://$(find robot_arm_description)/meshes/wrist_1.stl" scale="0.001 0.001 0.001"/>
      </geometry>
    </collision>
  </link>

  <link name="gripper_lower_1">
    <inertial>
      <origin xyz="0.02460528779031134 -0.005202121295352786 0.021097242066416055" rpy="0 0 0"/>
      <mass value="0.8259076503135568"/>
      <inertia ixx="0.000593" iyy="0.000592" izz="0.000298" ixy="-1e-06" iyz="8e-06" ixz="-2.6e-05"/>
    </inertial>
    <visual>
      <origin xyz="0.025936 -0.009864 -0.799847" rpy="0 0 0"/>
      <geometry>
        <mesh filename="file://$(find robot_arm_description)/meshes/gripper_lower_1.stl" scale="0.001 0.001 0.001"/>
      </geometry>
      <material name="silver">
        <color rgba="0.700 0.700 0.700 1.000"/>
      </material>
    </visual>
    <collision>
      <origin xyz="0.025936 -0.009864 -0.799847" rpy="0 0 0"/>
      <geometry>
        <mesh filename="file://$(find robot_arm_description)/meshes/gripper_lower_1.stl" scale="0.001 0.001 0.001"/>
      </geometry>
    </collision>
  </link>

  <link name="gripper_1">
    <inertial>
      <origin xyz="4.1334830649312863e-08 5.6910818703979904e-05 0.047248472649566" rpy="0 0 0"/>
      <mass value="0.34292143602258635"/>
      <inertia ixx="0.00018" iyy="0.00016" izz="0.000117" ixy="-0.0" iyz="-3e-06" ixz="-0.0"/>
    </inertial>
    <visual>
      <origin xyz="-0.000707 -0.004932 -0.865848" rpy="0 0 0"/>
      <geometry>
        <mesh filename="file://$(find robot_arm_description)/meshes/gripper_1.stl" scale="0.001 0.001 0.001"/>
      </geometry>
      <material name="silver">
        <color rgba="0.700 0.700 0.700 1.000"/>
      </material>
    </visual>
    <collision>
      <origin xyz="-0.000707 -0.004932 -0.865848" rpy="0 0 0"/>
      <geometry>
        <mesh filename="file://$(find robot_arm_description)/meshes/gripper_1.stl" scale="0.001 0.001 0.001"/>
      </geometry>
    </collision>
  </link>

  <link name="finger1_1">
    <inertial>
      <origin xyz="0.014167108604964743 -0.004750139292671366 0.0650419484784619" rpy="0 0 0"/>
      <mass value="0.251733155977348"/>
      <inertia ixx="0.000266" iyy="0.000288" izz="4.4e-05" ixy="-0.0" iyz="-0.0" ixz="-7.6e-05"/>
    </inertial>
    <visual>
      <origin xyz="0.030293 -0.009432 -0.913848" rpy="0 0 0"/>
      <geometry>
        <mesh filename="file://$(find robot_arm_description)/meshes/finger1_1.stl" scale="0.001 0.001 0.001"/>
      </geometry>
      <material name="silver">
        <color rgba="0.700 0.700 0.700 1.000"/>
      </material>
    </visual>
    <collision>
      <origin xyz="0.030293 -0.009432 -0.913848" rpy="0 0 0"/>
      <geometry>
        <mesh filename="file://$(find robot_arm_description)/meshes/finger1_1.stl" scale="0.001 0.001 0.001"/>
      </geometry>
    </collision>
  </link>

  <link name="finger2_1">
    <inertial>
      <origin xyz="-0.014167022019747452 -0.004724849659497038 0.06504194758265003" rpy="0 0 0"/>
      <mass value="0.2517331559773438"/>
      <inertia ixx="0.000266" iyy="0.000288" izz="4.4e-05" ixy="-0.0" iyz="0.0" ixz="7.6e-05"/>
    </inertial>
    <visual>
      <origin xyz="-0.031707 -0.009432 -0.913848" rpy="0 0 0"/>
      <geometry>
        <mesh filename="file://$(find robot_arm_description)/meshes/finger2_1.stl" scale="0.001 0.001 0.001"/>
      </geometry>
      <material name="silver">
        <color rgba="0.700 0.700 0.700 1.000"/>
      </material>
    </visual>
    <collision>
      <origin xyz="-0.031707 -0.009432 -0.913848" rpy="0 0 0"/>
      <geometry>
        <mesh filename="file://$(find robot_arm_description)/meshes/finger2_1.stl" scale="0.001 0.001 0.001"/>
      </geometry>
    </collision>
  </link>

  <joint name="shoulder_joint" type="revolute">
    <origin xyz="0.03435 0.0 0.194998" rpy="0 0 0"/>
    <parent link="base_link"/>
    <child link="shoulder_1"/>
    <axis xyz="-1.0 0.0 -0.0"/>
    <limit upper="1.570796" lower="-1.570796" effort="100" velocity="100"/>
  </joint>

  <joint name="elbow_joint" type="revolute">
    <origin xyz="-0.056 0.0 0.304849" rpy="0 0 0"/>
    <parent link="shoulder_1"/>
    <child link="elbow_1"/>
    <axis xyz="1.0 -0.0 -0.0"/>
    <limit upper="1.570796" lower="-1.570796" effort="100" velocity="100"/>
  </joint>

  <joint name="wrist_joint" type="revolute">
    <origin xyz="0.019507 0.004932 0.057087" rpy="0 0 0"/>
    <parent link="elbow_1"/>
    <child link="wrist_1"/>
    <axis xyz="0.0 -0.0 1.0"/>
    <limit upper="0.785398" lower="-0.785398" effort="100" velocity="100"/>
  </joint>

  <joint name="gripper_lower_joint" type="revolute">
    <origin xyz="-0.023793 0.004932 0.242913" rpy="0 0 0"/>
    <parent link="wrist_1"/>
    <child link="gripper_lower_1"/>
    <axis xyz="1.0 -0.0 -0.0"/>
    <limit upper="0.785398" lower="-0.785398" effort="100" velocity="100"/>
  </joint>

  <joint name="gripper_joint" type="revolute">
    <origin xyz="0.026643 -0.004932 0.066001" rpy="0 0 0"/>
    <parent link="gripper_lower_1"/>
    <child link="gripper_1"/>
    <axis xyz="0.0 0.0 1.0"/>
    <limit upper="0.785398" lower="-0.785398" effort="100" velocity="100"/>
  </joint>

  <joint name="finger1_joint" type="revolute">
    <origin xyz="-0.031 0.0045 0.048" rpy="0 0 0"/>
    <parent link="gripper_1"/>
    <child link="finger1_1"/>
    <axis xyz="0.0 1.0 -0.0"/>
    <limit upper="0.0" lower="-0.785398" effort="100" velocity="100"/>
  </joint>

  <joint name="finger2_joint" type="revolute">
    <origin xyz="0.031 0.0045 0.048" rpy="0 0 0"/>
    <parent link="gripper_1"/>
    <child link="finger2_1"/>
    <axis xyz="0.0 1.0 -0.0"/>
    <limit upper="0.785398" lower="0.0" effort="100" velocity="100"/>
  </joint>

  <gazebo reference="base_link">
    <material>Gazebo/Silver</material>
    <mu1>0.2</mu1>
    <mu2>0.2</mu2>
    <selfCollide>true</selfCollide>
    <gravity>true</gravity>
  </gazebo>

  <gazebo reference="shoulder_1">
    <material>Gazebo/Silver</material>
    <mu1>0.2</mu1>
    <mu2>0.2</mu2>
    <selfCollide>true</selfCollide>
  </gazebo>

  <gazebo reference="elbow_1">
    <material>Gazebo/Silver</material>
    <mu1>0.2</mu1>
    <mu2>0.2</mu2>
    <selfCollide>true</selfCollide>
  </gazebo>

  <gazebo reference="wrist_1">
    <material>Gazebo/Silver</material>
    <mu1>0.2</mu1>
    <mu2>0.2</mu2>
    <selfCollide>true</selfCollide>
  </gazebo>

  <gazebo reference="gripper_lower_1">
    <material>Gazebo/Silver</material>
    <mu1>0.2</mu1>
    <mu2>0.2</mu2>
    <selfCollide>true</selfCollide>
  </gazebo>

  <gazebo reference="gripper_1">
    <material>Gazebo/Silver</material>
    <mu1>0.2</mu1>
    <mu2>0.2</mu2>
    <selfCollide>true</selfCollide>
  </gazebo>

  <gazebo reference="finger1_1">
    <material>Gazebo/Silver</material>
    <mu1>0.2</mu1>
    <mu2>0.2</mu2>
    <selfCollide>true</selfCollide>
  </gazebo>

  <gazebo reference="finger2_1">
    <material>Gazebo/Silver</material>
    <mu1>0.2</mu1>
    <mu2>0.2</mu2>
    <selfCollide>true</selfCollide>
  </gazebo>

</robot>
